try{
    let a = 0;
    console.log(t)
}
catch(err){
    console.log(err);
    console.log(hello);
}
finally{
    console.log("Hello world");
}
// finally clause runs even if the catch block has error